Workbook

Sheet Sheet
A1: SUBSISTEMA DE CONTABILIDAD
A2: TRANSAMBIENTAL S.A.S.
A3: CONSULTA DE MOVIMIENTO POR FUENTES A 26.AGO./2025
A4: PERIODO COMPRENDIDO ENTRE 01.ENE./2025 Y 31.JUL./2025 | I4: =SUBTOTAL(9,I7:I521) -> 109263756 | J4: =SUBTOTAL(9,J7:J521) -> 96904517 | K4: =+I4-J4 -> 12359239
A6: Codigo Cuenta | B6: Nombre Cuenta | C6: Fecha Documento | D6: Fuente | E6: Nombre Fuente | F6: Prefijo Documento | G6: Numero Documento | H6: Detalle del Registro | I6: Valor Debito | J6: Valor Credito | K6: Tipo Anexo | L6: Id.Tercero | M6: Nombre Tercero | N6: Codigo Costo | O6: Nombre Costo | P6: Codigo Retencion | Q6: Concepto Retencion | R6: Base Retencion | S6: Tipo Libro | T6: Asiento Cierre | U6: Documento Referencia | V6: Numero Cheque | W6: Codigo Operacion | X6: Fecha Operacion | Y6: Programa | Z6: Estacion | AA6: Empresa | AB6: Fecha Version | AC6: Estado Reg.
A7: 138020001 | B7: REINTEGRO DE INCAPACIDADES | C7: 45681 | D7: 15 | E7: CONSIGNACIONES BANCO | G7: 000000701 | H7: SALUD TOTAL S.A. EPS ARS:REINTEGRO INCAPACIDAD000000701 | I7: 0 | J7: 433330 | K7: 1 | L7: 800130907 | M7: SALUD TOTAL S.A. EPS ARS | R7: 0 | S7: CONTABLE | T7: N | U7: 000000701 | V7: 0 | W7: TACOTESO | X7: Feb 6 2025 2:03PM | Y7: frmBAN607 | Z7: TA-COOR-TESO | AA7: TAMBIENTAL | AB7: Feb 6 2025 2:03PM
A8: 138020001 | B8: REINTEGRO DE INCAPACIDADES | C8: 45679 | D8: 15 | E8: CONSIGNACIONES BANCO | G8: 000000702 | H8: E.P.S. SANITAS S.A.:REINTEGRO INCAPACIDAD000000702 | I8: 0 | J8: 718378 | K8: 1 | L8: 800251440 | M8: E.P.S. SANITAS S.A. | R8: 0 | S8: CONTABLE | T8: N | U8: 000000702 | V8: 0 | W8: TACOTESO | X8: Feb 6 2025 2:04PM | Y8: frmBAN607 | Z8: TA-COOR-TESO | AA8: TAMBIENTAL | AB8: Feb 6 2025 2:04PM
A9: 138020001 | B9: REINTEGRO DE INCAPACIDADES | C9: 45674 | D9: 15 | E9: CONSIGNACIONES BANCO | G9: 000000703 | H9: E.P.S. SANITAS S.A.:REINTEGRO INCAPACIDAD000000703 | I9: 0 | J9: 2463437 | K9: 1 | L9: 800251440 | M9: E.P.S. SANITAS S.A. | R9: 0 | S9: CONTABLE | T9: N | U9: 000000703 | V9: 0 | W9: TACOTESO | X9: Feb 6 2025 2:05PM | Y9: frmBAN607 | Z9: TA-COOR-TESO | AA9: TAMBIENTAL | AB9: Feb 6 2025 2:05PM
A10: 138020001 | B10: REINTEGRO DE INCAPACIDADES | C10: 45671 | D10: 15 | E10: CONSIGNACIONES BANCO | G10: 000000704 | H10: EPS SURA COMPAÑIA SURAMERICANA SERVICIOS DE SALUD:REINTEGRO INCAPACIDAD000000704 | I10: 0 | J10: 2165553 | K10: 1 | L10: 800088702 | M10: EPS SURA COMPAÑIA SURAMERICANA SERVICIOS DE SALUD | R10: 0 | S10: CONTABLE | T10: N | U10: 000000704 | V10: 0 | W10: TACOTESO | X10: Feb 6 2025 2:06PM | Y10: frmBAN607 | Z10: TA-COOR-TESO | AA10: TAMBIENTAL | AB10: Feb 6 2025 2:06PM
A11: 138020001 | B11: REINTEGRO DE INCAPACIDADES | C11: 45667 | D11: 15 | E11: CONSIGNACIONES BANCO | G11: 000000706 | H11: NUEVA EMPRESA PROMOTORA DE SALUD:REINTEGRO INCAPACIDAD000000706 | I11: 0 | J11: 780001 | K11: 1 | L11: 900156264 | M11: NUEVA EMPRESA PROMOTORA DE SALUD | R11: 0 | S11: CONTABLE | T11: N | U11: 000000706 | V11: 0 | W11: TACOTESO | X11: Feb 6 2025 2:08PM | Y11: frmBAN607 | Z11: TA-COOR-TESO | AA11: TAMBIENTAL | AB11: Feb 6 2025 2:08PM
A12: 138020001 | B12: REINTEGRO DE INCAPACIDADES | C12: 45667 | D12: 15 | E12: CONSIGNACIONES BANCO | G12: 000000705 | H12: SALUD TOTAL S.A. EPS ARS:REINTEGRO INCAPACIDAD000000705 | I12: 0 | J12: 942452 | K12: 1 | L12: 800130907 | M12: SALUD TOTAL S.A. EPS ARS | R12: 0 | S12: CONTABLE | T12: N | U12: 000000705 | V12: 0 | W12: TACOTESO | X12: Feb 6 2025 2:07PM | Y12: frmBAN607 | Z12: TA-COOR-TESO | AA12: TAMBIENTAL | AB12: Feb 6 2025 2:07PM
A13: 138020001 | B13: REINTEGRO DE INCAPACIDADES | C13: 45688 | D13: 21 | E13: NOMINA NOVASOFT | G13: 000000043 | H13: GASTOS REEMBOLSABLES | I13: 711750 | J13: 0 | K13: 1 | L13: 73169783 | M13: VERGARA ORTEGA BERCELIO | N13: 10030400 | O13: OPERADORES | R13: 0 | S13: CONTABLE | T13: N | U13: 000000043 | V13: 0 | W13: TAAUXAREA | X13: Feb 18 2025 9:10AM | Y13: frmCON6093 | Z13: TA-ANA-CONT | AA13: TAMBIENTAL | AB13: Feb 18 2025 9:10AM
A14: 138020001 | B14: REINTEGRO DE INCAPACIDADES | C14: 45688 | D14: 21 | E14: NOMINA NOVASOFT | G14: 000000043 | H14: GASTOS REEMBOLSABLES | I14: 711750 | J14: 0 | K14: 1 | L14: 73169783 | M14: VERGARA ORTEGA BERCELIO | N14: 10030400 | O14: OPERADORES | R14: 0 | S14: CONTABLE | T14: N | U14: 000000043 | V14: 0 | W14: TAAUXAREA | X14: Feb 18 2025 9:10AM | Y14: frmCON6093 | Z14: TA-ANA-CONT | AA14: TAMBIENTAL | AB14: Feb 18 2025 9:10AM
A15: 138020001 | B15: REINTEGRO DE INCAPACIDADES | C15: 45688 | D15: 21 | E15: NOMINA NOVASOFT | G15: 000000043 | H15: GASTOS REEMBOLSABLES | I15: 49214 | J15: 0 | K15: 1 | L15: 73579382 | M15: HENRRY VARGAS CHICO | N15: 10030400 | O15: OPERADORES | R15: 0 | S15: CONTABLE | T15: N | U15: 000000043 | V15: 0 | W15: TAAUXAREA | X15: Feb 18 2025 9:10AM | Y15: frmCON6093 | Z15: TA-ANA-CONT | AA15: TAMBIENTAL | AB15: Feb 18 2025 9:10AM
A16: 138020001 | B16: REINTEGRO DE INCAPACIDADES | C16: 45688 | D16: 21 | E16: NOMINA NOVASOFT | G16: 000000043 | H16: GASTOS REEMBOLSABLES | I16: 449970 | J16: 0 | K16: 1 | L16: 72195323 | M16: LUIS ALFONSO UPARELA LARA | N16: 10020200 | O16: EJECUCIÓN | R16: 0 | S16: CONTABLE | T16: N | U16: 000000043 | V16: 0 | W16: TAAUXAREA | X16: Feb 18 2025 9:10AM | Y16: frmCON6093 | Z16: TA-ANA-CONT | AA16: TAMBIENTAL | AB16: Feb 18 2025 9:10AM
A17: 138020001 | B17: REINTEGRO DE INCAPACIDADES | C17: 45688 | D17: 21 | E17: NOMINA NOVASOFT | G17: 000000043 | H17: GASTOS REEMBOLSABLES | I17: 47450 | J17: 0 | K17: 1 | L17: 1002059942 | M17: WILSON RAFAEL SIMANCAS MARTINEZ | N17: 10030400 | O17: OPERADORES | R17: 0 | S17: CONTABLE | T17: N | U17: 000000043 | V17: 0 | W17: TAAUXAREA | X17: Feb 18 2025 9:10AM | Y17: frmCON6093 | Z17: TA-ANA-CONT | AA17: TAMBIENTAL | AB17: Feb 18 2025 9:10AM
A18: 138020001 | B18: REINTEGRO DE INCAPACIDADES | C18: 45688 | D18: 21 | E18: NOMINA NOVASOFT | G18: 000000043 | H18: GASTOS REEMBOLSABLES | I18: 152520 | J18: 0 | K18: 1 | L18: 1050959328 | M18: WILMER ANTONIO SILVA VARGAS | N18: 10030400 | O18: OPERADORES | R18: 0 | S18: CONTABLE | T18: N | U18: 000000043 | V18: 0 | W18: TAAUXAREA | X18: Feb 18 2025 9:10AM | Y18: frmCON6093 | Z18: TA-ANA-CONT | AA18: TAMBIENTAL | AB18: Feb 18 2025 9:10AM
A19: 138020001 | B19: REINTEGRO DE INCAPACIDADES | C19: 45688 | D19: 21 | E19: NOMINA NOVASOFT | G19: 000000043 | H19: GASTOS REEMBOLSABLES | I19: 142350 | J19: 0 | K19: 1 | L19: 73211365 | M19: SIERRA PAYARES RAFAEL | N19: 10030400 | O19: OPERADORES | R19: 0 | S19: CONTABLE | T19: N | U19: 000000043 | V19: 0 | W19: TAAUXAREA | X19: Feb 18 2025 9:10AM | Y19: frmCON6093 | Z19: TA-ANA-CONT | AA19: TAMBIENTAL | AB19: Feb 18 2025 9:10AM
A20: 138020001 | B20: REINTEGRO DE INCAPACIDADES | C20: 45688 | D20: 21 | E20: NOMINA NOVASOFT | G20: 000000043 | H20: GASTOS REEMBOLSABLES | I20: 47450 | J20: 0 | K20: 1 | L20: 9103870 | M20: SALAS LLERENA OSVALDO | N20: 10030400 | O20: OPERADORES | R20: 0 | S20: CONTABLE | T20: N | U20: 000000043 | V20: 0 | W20: TAAUXAREA | X20: Feb 18 2025 9:10AM | Y20: frmCON6093 | Z20: TA-ANA-CONT | AA20: TAMBIENTAL | AB20: Feb 18 2025 9:10AM
A21: 138020001 | B21: REINTEGRO DE INCAPACIDADES | C21: 45688 | D21: 21 | E21: NOMINA NOVASOFT | G21: 000000043 | H21: GASTOS REEMBOLSABLES | I21: 379600 | J21: 0 | K21: 1 | L21: 1047463607 | M21: DUBAN JOSE RODRIGUEZ DIAZ | N21: 10030400 | O21: OPERADORES | R21: 0 | S21: CONTABLE | T21: N | U21: 000000043 | V21: 0 | W21: TAAUXAREA | X21: Feb 18 2025 9:10AM | Y21: frmCON6093 | Z21: TA-ANA-CONT | AA21: TAMBIENTAL | AB21: Feb 18 2025 9:10AM
A22: 138020001 | B22: REINTEGRO DE INCAPACIDADES | C22: 45688 | D22: 21 | E22: NOMINA NOVASOFT | G22: 000000043 | H22: GASTOS REEMBOLSABLES | I22: 94900 | J22: 0 | K22: 1 | L22: 94379411 | M22: RINCON SANCHEZ ANDERSON | N22: 10030400 | O22: OPERADORES | R22: 0 | S22: CONTABLE | T22: N | U22: 000000043 | V22: 0 | W22: TAAUXAREA | X22: Feb 18 2025 9:10AM | Y22: frmCON6093 | Z22: TA-ANA-CONT | AA22: TAMBIENTAL | AB22: Feb 18 2025 9:10AM
A23: 138020001 | B23: REINTEGRO DE INCAPACIDADES | C23: 45688 | D23: 21 | E23: NOMINA NOVASOFT | G23: 000000043 | H23: GASTOS REEMBOLSABLES | I23: 47450 | J23: 0 | K23: 1 | L23: 7921809 | M23: NICOLAS REYES CASIANI | N23: 10030400 | O23: OPERADORES | R23: 0 | S23: CONTABLE | T23: N | U23: 000000043 | V23: 0 | W23: TAAUXAREA | X23: Feb 18 2025 9:10AM | Y23: frmCON6093 | Z23: TA-ANA-CONT | AA23: TAMBIENTAL | AB23: Feb 18 2025 9:10AM
A24: 138020001 | B24: REINTEGRO DE INCAPACIDADES | C24: 45688 | D24: 21 | E24: NOMINA NOVASOFT | G24: 000000043 | H24: GASTOS REEMBOLSABLES | I24: 664300 | J24: 0 | K24: 1 | L24: 3883113 | M24: LUIS FERNANDO PIMIENTEL SANTANA | N24: 10030400 | O24: OPERADORES | R24: 0 | S24: CONTABLE | T24: N | U24: 000000043 | V24: 0 | W24: TAAUXAREA | X24: Feb 18 2025 9:10AM | Y24: frmCON6093 | Z24: TA-ANA-CONT | AA24: TAMBIENTAL | AB24: Feb 18 2025 9:10AM
... A77: 138020001 | B77: REINTEGRO DE INCAPACIDADES | C77: 45716 | D77: 21 | E77: NOMINA NOVASOFT | G77: 000000044 | H77: GASTOS REEMBOLSABLES | I77: 142350 | J77: 0 | K77: 1 | L77: 1237441830 | M77: ABRAM GARRIDO BARACALDO | N77: 10030400 | O77: OPERADORES | R77: 0 | S77: CONTABLE | T77: N | U77: 000000044 | V77: 0 | W77: TAAUXAREA | X77: Mar 20 2025 5:19PM | Y77: frmCON6093 | Z77: TA-AUX-CONTA1 | AA77: TAMBIENTAL | AB77: Mar 20 2025 5:19PM
A78: 138020001 | B78: REINTEGRO DE INCAPACIDADES | C78: 45713 | D78: 15 | E78: CONSIGNACIONES BANCO | G78: 000000745 | H78: E.P.S. SANITAS S.A.:REINTEGRO INCAPACIDADES000000745 | I78: 0 | J78: 130000 | K78: 1 | L78: 73211365 | M78: SIERRA PAYARES RAFAEL | R78: 0 | S78: CONTABLE | T78: N | U78: 000000745 | V78: 0 | W78: TACOTESO | X78: Mar 14 2025 5:22PM | Y78: frmBAN607 | Z78: TA-COOR-TESO | AA78: TAMBIENTAL | AB78: Mar 14 2025 5:22PM
A79: 138020001 | B79: REINTEGRO DE INCAPACIDADES | C79: 45713 | D79: 15 | E79: CONSIGNACIONES BANCO | G79: 000000744 | H79: EPS SURA COMPAÑIA SURAMERICANA SERVICIOS DE SALUD:REINTEGRO INCAPACIDADES000000744 | I79: 0 | J79: 596267 | K79: 1 | L79: 3883113 | M79: LUIS FERNANDO PIMIENTEL SANTANA | R79: 0 | S79: CONTABLE | T79: N | U79: 000000744 | V79: 0 | W79: TACOTESO | X79: Mar 14 2025 5:19PM | Y79: frmBAN607 | Z79: TA-COOR-TESO | AA79: TAMBIENTAL | AB79: Mar 14 2025 5:19PM
A80: 138020001 | B80: REINTEGRO DE INCAPACIDADES | C80: 45712 | D80: 15 | E80: CONSIGNACIONES BANCO | G80: 000000743 | H80: E.P.S. SANITAS S.A.:REINTEGRO INCAPACIDAD000000743 | I80: 0 | J80: 91488 | K80: 1 | L80: 1002248481 | M80: SERGIO LUIS HERNANDEZ GONZALEZ | R80: 0 | S80: CONTABLE | T80: N | U80: 000000743 | V80: 0 | W80: TACOTESO | X80: Mar 14 2025 5:17PM | Y80: frmBAN607 | Z80: TA-COOR-TESO | AA80: TAMBIENTAL | AB80: Mar 14 2025 5:17PM
A81: 138020001 | B81: REINTEGRO DE INCAPACIDADES | C81: 45709 | D81: 15 | E81: CONSIGNACIONES BANCO | G81: 000000742 | H81: COOSALUD ENTIDAD PROMOTORA DE SALUD S.A:REINTEGRO INCAPACIDADES000000742 | I81: 0 | J81: 44768 | K81: 1 | L81: 1047430645 | M81: LUIS MODESTO PALACIO URANGO | R81: 0 | S81: CONTABLE | T81: N | U81: 000000742 | V81: 0 | W81: TACOTESO | X81: Mar 14 2025 5:11PM | Y81: frmBAN607 | Z81: TA-COOR-TESO | AA81: TAMBIENTAL | AB81: Mar 14 2025 5:11PM
A82: 138020001 | B82: REINTEGRO DE INCAPACIDADES | C82: 45709 | D82: 15 | E82: CONSIGNACIONES BANCO | G82: 000000741 | H82: COOSALUD ENTIDAD PROMOTORA DE SALUD S.A:REINTEGRO INCAPACIDADES000000741 | I82: 0 | J82: 44768 | K82: 1 | L82: 1047430645 | M82: LUIS MODESTO PALACIO URANGO | R82: 0 | S82: CONTABLE | T82: N | U82: 000000741 | V82: 0 | W82: TACOTESO | X82: Mar 14 2025 5:10PM | Y82: frmBAN607 | Z82: TA-COOR-TESO | AA82: TAMBIENTAL | AB82: Mar 14 2025 5:10PM
A83: 138020001 | B83: REINTEGRO DE INCAPACIDADES | C83: 45709 | D83: 15 | E83: CONSIGNACIONES BANCO | G83: 000000740 | H83: COOSALUD ENTIDAD PROMOTORA DE SALUD S.A:REINTEGRO INCAPACIDADES000000740 | I83: 0 | J83: 47450 | K83: 1 | L83: 73117655 | M83: WILMAN HERRERA ARROYO | R83: 0 | S83: CONTABLE | T83: N | U83: 000000740 | V83: 0 | W83: TACOTESO | X83: Mar 14 2025 5:08PM | Y83: frmBAN607 | Z83: TA-COOR-TESO | AA83: TAMBIENTAL | AB83: Mar 14 2025 5:08PM
A84: 138020001 | B84: REINTEGRO DE INCAPACIDADES | C84: 45709 | D84: 15 | E84: CONSIGNACIONES BANCO | G84: 000000739 | H84: COOSALUD ENTIDAD PROMOTORA DE SALUD S.A:REINTEGRO INCAPACIDADES000000739 | I84: 0 | J84: 47450 | K84: 1 | L84: 73117655 | M84: WILMAN HERRERA ARROYO | R84: 0 | S84: CONTABLE | T84: N | U84: 000000739 | V84: 0 | W84: TACOTESO | X84: Mar 14 2025 5:06PM | Y84: frmBAN607 | Z84: TA-COOR-TESO | AA84: TAMBIENTAL | AB84: Mar 14 2025 5:06PM
A85: 138020001 | B85: REINTEGRO DE INCAPACIDADES | C85: 45709 | D85: 15 | E85: CONSIGNACIONES BANCO | G85: 000000738 | H85: Reintegro incapacidades | I85: 0 | J85: 43431 | K85: 1 | L85: 15031784 | M85: LOKY LUCIANO PEREZ CHICA | R85: 0 | S85: CONTABLE | T85: N | U85: 000000738 | V85: 0 | W85: TACOTESO | X85: Mar 14 2025 4:58PM | Y85: frmBAN607 | Z85: TA-COOR-TESO | AA85: TAMBIENTAL | AB85: Mar 14 2025 4:58PM
A86: 138020001 | B86: REINTEGRO DE INCAPACIDADES | C86: 45709 | D86: 15 | E86: CONSIGNACIONES BANCO | G86: 000000738 | H86: Reintegro incapacidades | I86: 0 | J86: 86667 | K86: 1 | L86: 1002059942 | M86: WILSON RAFAEL SIMANCAS MARTINEZ | R86: 0 | S86: CONTABLE | T86: N | U86: 000000738 | V86: 0 | W86: TACOTESO | X86: Mar 14 2025 4:58PM | Y86: frmBAN607 | Z86: TA-COOR-TESO | AA86: TAMBIENTAL | AB86: Mar 14 2025 4:58PM
A87: 138020001 | B87: REINTEGRO DE INCAPACIDADES | C87: 45709 | D87: 15 | E87: CONSIGNACIONES BANCO | G87: 000000738 | H87: Reintegro incapacidades | I87: 0 | J87: 1213333 | K87: 1 | L87: 12595533 | M87: LUIS ALFONSO MEDINA OCHOA | R87: 0 | S87: CONTABLE | T87: N | U87: 000000738 | V87: 0 | W87: TACOTESO | X87: Mar 14 2025 4:58PM | Y87: frmBAN607 | Z87: TA-COOR-TESO | AA87: TAMBIENTAL | AB87: Mar 14 2025 4:58PM
A88: 138020001 | B88: REINTEGRO DE INCAPACIDADES | C88: 45709 | D88: 15 | E88: CONSIGNACIONES BANCO | G88: 000000738 | H88: NUEVA EMPRESA PROMOTORA DE SALUD:Reintegro incapacidades000000738 | I88: 0 | J88: 1993333 | K88: 1 | L88: 73159298 | M88: MARQUEZ MERCADO ALEXANDER RAFAEL | R88: 0 | S88: CONTABLE | T88: N | U88: 000000738 | V88: 0 | W88: TACOTESO | X88: Mar 14 2025 4:58PM | Y88: frmBAN607 | Z88: TA-COOR-TESO | AA88: TAMBIENTAL | AB88: Mar 14 2025 4:58PM
A89: 138020001 | B89: REINTEGRO DE INCAPACIDADES | C89: 45706 | D89: 15 | E89: CONSIGNACIONES BANCO | G89: 000000737 | H89: E.P.S. SANITAS S.A.:REINTEGRO INCAPACIDAD000000737 | I89: 0 | J89: 50862 | K89: 1 | L89: 1002248481 | M89: SERGIO LUIS HERNANDEZ GONZALEZ | R89: 0 | S89: CONTABLE | T89: N | U89: 000000737 | V89: 0 | W89: TACOTESO | X89: Mar 14 2025 3:20PM | Y89: frmBAN607 | Z89: TA-COOR-TESO | AA89: TAMBIENTAL | AB89: Mar 14 2025 3:20PM
... A94: 138020001 | B94: REINTEGRO DE INCAPACIDADES | C94: 45720 | D94: 15 | E94: CONSIGNACIONES BANCO | G94: 000000764 | H94: ASOCIACION MUTUAL SER EMPRESA SOLIDARIA:REINTEGRO INCAPACIDAD000000764 | I94: 0 | J94: 133690 | K94: 1 | L94: 806008394 | M94: ASOCIACION MUTUAL SER EMPRESA SOLIDARIA | R94: 0 | S94: CONTABLE | T94: N | U94: 000000764 | V94: 0 | W94: TACOTESO | X94: Abr 8 2025 5:08PM | Y94: frmBAN607 | Z94: TA-COOR-TESO | AA94: TAMBIENTAL | AB94: Abr 8 2025 5:08PM
A95: 138020001 | B95: REINTEGRO DE INCAPACIDADES | C95: 45747 | D95: 21 | E95: NOMINA NOVASOFT | G95: 000000045 | H95: GASTOS REEMBOLSABLES | I95: 521950 | J95: 0 | K95: 1 | L95: 73159298 | M95: MARQUEZ MERCADO ALEXANDER RAFAEL | N95: 10030400 | O95: OPERADORES | R95: 0 | S95: CONTABLE | T95: N | U95: 000000045 | V95: 0 | W95: TAAUXAREA | X95: Abr 22 2025 12:04PM | Y95: frmCON6093 | Z95: TA-ANA-CONTB | AA95: TAMBIENTAL | AB95: Abr 22 2025 12:04PM
A96: 138020001 | B96: REINTEGRO DE INCAPACIDADES | C96: 45747 | D96: 21 | E96: NOMINA NOVASOFT | G96: 000000045 | H96: GASTOS REEMBOLSABLES | I96: 94900 | J96: 0 | K96: 1 | L96: 30873721 | M96: ROSANA JIMENEZ LLANOS | N96: 10030400 | O96: OPERADORES | R96: 0 | S96: CONTABLE | T96: N | U96: 000000045 | V96: 0 | W96: TAAUXAREA | X96: Abr 22 2025 12:04PM | Y96: frmCON6093 | Z96: TA-ANA-CONTB | AA96: TAMBIENTAL | AB96: Abr 22 2025 12:04PM
A97: 138020001 | B97: REINTEGRO DE INCAPACIDADES | C97: 45747 | D97: 21 | E97: NOMINA NOVASOFT | G97: 000000045 | H97: GASTOS REEMBOLSABLES | I97: 759200 | J97: 0 | K97: 1 | L97: 73109356 | M97: WILLIAN ANTONIO MARTINEZ OLAVE | N97: 10030400 | O97: OPERADORES | R97: 0 | S97: CONTABLE | T97: N | U97: 000000045 | V97: 0 | W97: TAAUXAREA | X97: Abr 22 2025 12:04PM | Y97: frmCON6093 | Z97: TA-ANA-CONTB | AA97: TAMBIENTAL | AB97: Abr 22 2025 12:04PM
...

Sheet Comportamiento
B2: COMPORTAMIENTO DE INCAPACIDADES 2021 - 2026
F4: 2021 | I4: 2022 | L4: 2023 | O4: 2024 | R4: 2025 | U4: 2026
B5: Tem_Cuenta | C5: Tem_Nom Cta | D5: Generado | E5: Recuperado | F5: Sal Act 2021 | G5: Generado | H5: Recuperado | I5: Sal Act 2022 | J5: Generado | K5: Recuperado | L5: Sal Act 2023 | M5: Generado | N5: Recuperado | O5: Sal Act 2024 | P5: Generado | Q5: Recuperado | R5: Sal Act 2025 | S5: Generado | T5: Recuperado | U5: Sal Act 2026
B6: 138020001 | C6: REINTEGRO DE INCAPACIDADES | D6: =SUMIF('BD sin reclasif'!$D$7:$D$10000,Comportamiento!F4,'BD sin reclasif'!$J$7:$J$10000) -> 42950760 | E6: =SUMIF('BD sin reclasif'!$D$7:$D$10000,Comportamiento!F4,'BD sin reclasif'!$K$7:$K$10000) -> 3940992 | F6: =+D6-E6 -> 39009768 | G6: =SUMIF('BD sin reclasif'!$D$7:$D$10000,Comportamiento!I4,'BD sin reclasif'!$J$7:$J$10000) -> 66175156 | H6: =SUMIF('BD sin reclasif'!$D$7:$D$10000,Comportamiento!I4,'BD sin reclasif'!$K$7:$K$10000) -> 44088544 | I6: =+F6+G6-H6 -> 61096380 | J6: =SUMIF('BD sin reclasif'!$D$7:$D$10000,Comportamiento!L4,'BD sin reclasif'!$J$7:$J$10000) -> 129358157 | K6: =SUMIF('BD sin reclasif'!$D$7:$D$10000,Comportamiento!L4,'BD sin reclasif'!$K$7:$K$10000) -> 24346262 | L6: =+I6+J6-K6 -> 1.6610828e+08 | M6: =SUMIF('BD sin reclasif'!$D$7:$D$10000,Comportamiento!O4,'BD sin reclasif'!$J$7:$J$10000) -> 189024323 | N6: =SUMIF('BD sin reclasif'!$D$7:$D$9442,Comportamiento!O4,'BD sin reclasif'!$K$7:$K$9442) -> 178759490 | O6: =+L6+M6-N6 -> 1.7637311e+08 | P6: =SUMIF('BD sin reclasif'!$D$7:$D$10000,Comportamiento!R4,'BD sin reclasif'!$J$7:$J$10000) -> 91449382 | Q6: =SUMIF('BD sin reclasif'!$D$7:$D$9442,Comportamiento!R4,'BD sin reclasif'!$K$7:$K$9442) -> 88178930 | R6: =+O6+P6-Q6 -> 1.7964356e+08 | S6: =SUMIF('BD sin reclasif'!$D$7:$D$10000,Comportamiento!U4,'BD sin reclasif'!$J$7:$J$10000) -> 13425056 | T6: =SUMIF('BD sin reclasif'!$D$7:$D$9442,Comportamiento!U4,'BD sin reclasif'!$K$7:$K$9442) -> 10261364 | U6: =+R6+S6-T6 -> 1.8280725e+08
F8: 2021 | I8: 2022 | L8: 2023 | O8: 2024 | R8: 2025 | U8: 2026 | W8: Comentarios
C9: Saldo Inicial | F9: 0 | I9: =+F13 -> 39009768 | L9: =+I13 -> 61096380 | O9: =+L13 -> 1.6610828e+08 | R9: =+O13 -> 1.7637311e+08 | U9: =+R13 -> 1.7964356e+08
C10: (+) Generado | F10: =+D6 -> 42950760 | I10: =+G6 -> 66175156 | L10: =+J6 -> 129358157 | O10: =+M6 -> 189024323 | R10: =+P6 -> 91449382 | U10: =+S6 -> 13425056
C11: (-) Recuperado | F11: =-E6 -> -3940992 | I11: =-H6 -> -44088544 | L11: =-K6 -> -24346262 | O11: =-N6 -> -178759490 | R11: =-Q6 -> -88178930 | U11: =-T6 -> -10261364
C12: (-) Incobrable | F12: 0 | I12: 0 | L12: 0 | O12: 0 | R12: 0 | U12: 0
C13: Saldo Final | F13: =SUM(F9:F12) -> 39009768 | I13: =SUM(I9:I12) -> 61096380 | L13: =SUM(L9:L12) -> 1.6610828e+08 | O13: =SUM(O9:O12) -> 1.7637311e+08 | R13: =SUM(R9:R12) -> 1.7964356e+08 | U13: =SUM(U9:U12) -> 1.8280725e+08
B28: *Cifras en miles de peso

Sheet Detalle Gerencia
A1: EPS | B1: 2021 | C1: 2022 | D1: 2023 | E1: 2024 | F1: 2025 | G1: 2026 | H1: Total general | I1: %
A2: TRANSAMBIENTAL SAS | B2: 38623261 | G2: =+SUMIFS('BD sin reclasif'!$J:$J,'BD sin reclasif'!$AH:$AH,'Detalle Gerencia'!A2,'BD sin reclasif'!$AF:$AF,'Detalle Gerencia'!$G$1) -> 0 | H2: =SUM(B2:G2) -> 38623261 | I2: =+H2/$H$15 -> 0.19457405
A3: SALUD TOTAL E.P.S. | B3: 0 | C3: 2882465 | D3: =4667958+7496555 -> 12164513 | E3: =12135741-2000000 -> 10135741 | F3: =14144951-2000000 -> 12144951 | G3: =+SUMIFS('BD sin reclasif'!$J:$J,'BD sin reclasif'!$AH:$AH,'Detalle Gerencia'!A3,'BD sin reclasif'!$AF:$AF,'Detalle Gerencia'!$G$1) -> 4902540 | H3: =SUM(B3:G3) -> 42230210 | I3: =+H3/$H$15 -> 0.21274493
A4: SANITAS E.P.S | B4: 0 | C4: 2310456 | D4: =16952990-1000000-480533 -> 15472457 | E4: =6188650-2000000 -> 4188650 | F4: =5165577+5285863 -> 10451440 | G4: =+SUMIFS('BD sin reclasif'!$J:$J,'BD sin reclasif'!$AH:$AH,'Detalle Gerencia'!A4,'BD sin reclasif'!$AF:$AF,'Detalle Gerencia'!$G$1) -> 233455 | H4: =SUM(B4:G4) -> 32656458 | I4: =+H4/$H$15 -> 0.16451483
A5: EPS MUTUAL SER | B5: 0 | C5: 6782337 | D5: 6521414 | E5: 5476679 | F5: =6484188+8000000-1444921 -> 13039267 | G5: =+SUMIFS('BD sin reclasif'!$J:$J,'BD sin reclasif'!$AH:$AH,'Detalle Gerencia'!A5,'BD sin reclasif'!$AF:$AF,'Detalle Gerencia'!$G$1) -> 1623876 | H5: =SUM(B5:G5) -> 33443573 | I5: =+H5/$H$15 -> 0.16848011
A6: FAMISANAR E.P.S | B6: 0 | C6: 1328674 | D6: =7161414-4293000 -> 2868414 | E6: 1280000 | F6: =2485000+2000000 -> 4485000 | G6: =+SUMIFS('BD sin reclasif'!$J:$J,'BD sin reclasif'!$AH:$AH,'Detalle Gerencia'!A6,'BD sin reclasif'!$AF:$AF,'Detalle Gerencia'!$G$1) -> 1925997 | H6: =SUM(B6:G6) -> 11888085 | I6: =+H6/$H$15 -> 0.059889112
A7: SURA E.P.S. | B7: 0 | C7: 1810983 | D7: 3047344 | E7: =2991428+242467 -> 3233895 | F7: =2658540+4000000+1000000 -> 7658540 | G7: =+SUMIFS('BD sin reclasif'!$J:$J,'BD sin reclasif'!$AH:$AH,'Detalle Gerencia'!A7,'BD sin reclasif'!$AF:$AF,'Detalle Gerencia'!$G$1) -> 2626360 | H7: =SUM(B7:G7) -> 18377122 | I7: =+H7/$H$15 -> 0.092579209
A8: COOSALUD ESS EPS -S | B8: 0 | C8: 710325 | D8: 3407896 | E8: 966867 | F8: 3661949 | G8: =+SUMIFS('BD sin reclasif'!$J:$J,'BD sin reclasif'!$AH:$AH,'Detalle Gerencia'!A8,'BD sin reclasif'!$AF:$AF,'Detalle Gerencia'!$G$1) -> 0 | H8: =SUM(B8:G8) -> 8747037 | I8: =+H8/$H$15 -> 0.04406532
A9: NUEVA E.P.S | B9: 0 | C9: 0 | D9: 999324 | E9: 0 | F9: =2416853+1829196 -> 4246049 | G9: =+SUMIFS('BD sin reclasif'!$J:$J,'BD sin reclasif'!$AH:$AH,'Detalle Gerencia'!A9,'BD sin reclasif'!$AF:$AF,'Detalle Gerencia'!$G$1) -> 1176111 | H9: =SUM(B9:G9) -> 6421484 | I9: =+H9/$H$15 -> 0.032349783
A10: EPS-S CAJACOPI | B10: 0 | D10: 270668 | E10: 86667 | F10: 2229713 | G10: =+SUMIFS('BD sin reclasif'!$J:$J,'BD sin reclasif'!$AH:$AH,'Detalle Gerencia'!A10,'BD sin reclasif'!$AF:$AF,'Detalle Gerencia'!$G$1) -> 758728 | H10: =SUM(B10:G10) -> 3345776 | I10: =+H10/$H$15 -> 0.016855158
A11: FONDO DE SOLIDARIDAD Y GARANTÍA FOSYGA | C11: 972655 | D11: 685000 | E11: 563334 | F11: 0 | G11: =+SUMIFS('BD sin reclasif'!$J:$J,'BD sin reclasif'!$AH:$AH,'Detalle Gerencia'!A11,'BD sin reclasif'!$AF:$AF,'Detalle Gerencia'!$G$1) -> 0 | H11: =SUM(B11:G11) -> 2220989 | I11: =+H11/$H$15 -> 0.011188771
A12: COOMEVA E.P.S | B12: 0 | C12: 327939 | D12: 0 | G12: =+SUMIFS('BD sin reclasif'!$J:$J,'BD sin reclasif'!$AH:$AH,'Detalle Gerencia'!A12,'BD sin reclasif'!$AF:$AF,'Detalle Gerencia'!$G$1) -> 0 | H12: =SUM(B12:G12) -> 327939 | I12: =+H12/$H$15 -> 0.0016520723
A13: (en blanco) | C13: 41686 | G13: =+SUMIFS('BD sin reclasif'!$J:$J,'BD sin reclasif'!$AH:$AH,'Detalle Gerencia'!A13,'BD sin reclasif'!$AF:$AF,'Detalle Gerencia'!$G$1) -> 0 | H13: =SUM(B13:G13) -> 41686 | I13: =+H13/$H$15 -> 0.00021000334
A14: AMBUQ | G14: =+SUMIFS('BD sin reclasif'!$J:$J,'BD sin reclasif'!$AH:$AH,'Detalle Gerencia'!A14,'BD sin reclasif'!$AF:$AF,'Detalle Gerencia'!$G$1) -> 177989 | H14: =SUM(B14:G14) -> 177989
A15: Incapacidades a 2026 * EPS | B15: =SUM(B2:B13) -> 38623261 | C15: =SUM(C2:C13) -> 17167520 | D15: =SUM(D2:D13) -> 45437030 | E15: =SUM(E2:E13) -> 25931833 | F15: =SUM(F2:F13) -> 57916909 | G15: =SUM(G2:G14) -> 13425056 | H15: =SUM(H2:H14) -> 1.9850161e+08
A22: Generado | B22: =+Comportamiento!F10 -> 42950760 | C22: =+Comportamiento!I10 -> 66175156 | D22: =+Comportamiento!L10 -> 129358157 | E22: =+Comportamiento!O10 -> 189024323 | F22: =+Comportamiento!R10 -> 91449382 | G22: =+Comportamiento!S6 -> 13425056 | H22: =SUM(B22:G22) -> 5.3238283e+08
A23: Recaudado | B23: =+Comportamiento!F11*-1 -> 3940992 | C23: =+Comportamiento!I11*-1 -> 44088544 | D23: =+Comportamiento!L11*-1 -> 24346262 | E23: =+Comportamiento!O11*-1 -> 178759490 | F23: =+Comportamiento!R11*-1 -> 88178930 | G23: =+Comportamiento!T6 -> 10261364 | H23: =SUM(B23:G23) -> 349575582 | I23: =+H22-H23 -> 1.8280725e+08
A24: 2021 | B24: =3398127+542865 -> 3940992 | C24: =5546000+223908 -> 5769908 | D24: 0 | E24: 0 | F24: 49592 | H24: =SUM(B24:G24) -> 9760492 | I24: =+I23-Comportamiento!U6 -> 0
A25: 2022 | B25: 0 | C25: =22905000+15413636 -> 38318636 | D25: 4104000 | E25: 3992000 | F25: 2593000 | H25: =SUM(B25:G25) -> 49007636
A26: 2023 | B26: 0 | C26: 0 | D26: =+D23-D25 -> 20242262 | E26: =47423000+500000 -> 47923000 | F26: =3462865+8000000+4293000 -> 15755865 | G26: =1953742+1845170 -> 3798912 | H26: =SUM(B26:G26) -> 87720039
A27: 2024 | B27: 0 | C27: 0 | E27: 126844490 | F27: 36248000 | G27: 2181242 | H27: =SUM(B27:G27) -> 165273732
A28: 2025 | B28: 0 | C28: 0 | E28: 0 | F28: =45825473-8000000-4293000 -> 33532473 | G28: =2491485+1789725 -> 4281210 | H28: =SUM(B28:G28) -> 37813683
A29: 2026 | B29: 0 | C29: 0 | D29: 0 | E29: 0 | F29: 0 | G29: 0 | H29: =SUM(B29:G29) -> 0
A30: Incapacidades recaudadas | B30: =SUM(B24:B29) -> 3940992 | C30: =SUM(C24:C29) -> 44088544 | D30: =SUM(D24:D29) -> 24346262 | E30: =SUM(E24:E29) -> 178759490 | F30: =SUM(F24:F29) -> 88178930 | G30: =SUM(G24:G29) -> 10261364 | H30: =SUM(H24:H29) -> 349575582
B31: =B23=B30 -> TRUE | C31: =C23=C30 -> TRUE | D31: =D23=D30 -> TRUE | E31: =E23=E30 -> TRUE | F31: =F23=F30 -> TRUE | G31: =G23=G30 -> TRUE | H31: =H23=H30 -> TRUE
F32: =+F30-F23 -> 0 | G32: =+G23-G30 -> 0 | H32: =+H23-H30 -> 0
A34: Año | B34: Generado | C34: Recaudado | D34: Cartera Pte x recaudar
A35: 2021 | B35: =+B22 -> 42950760 | C35: =+H24 -> 9760492 | D35: =+B35-C35 -> 33190268
A36: 2022 | B36: =+C22 -> 66175156 | C36: =+H25 -> 49007636 | D36: =+B36-C36 -> 17167520
A37: 2023 | B37: =+D22 -> 129358157 | C37: =+H26 -> 87720039 | D37: =+B37-C37 -> 41638118
A38: 2024 | B38: =+E22 -> 189024323 | C38: =+H27 -> 165273732 | D38: =+B38-C38 -> 23750591
A39: 2025 | B39: =+F22 -> 91449382 | C39: =+H28 -> 37813683 | D39: =+B39-C39 -> 53635699
A40: 2026 | B40: =+G22 -> 13425056 | C40: =+G30 -> 10261364 | D40: =+B40-C40 -> 3163692
B41: =SUM(B35:B40) -> 5.3238283e+08 | C41: =SUM(C35:C40) -> 359836946 | D41: =SUM(D35:D40) -> 1.7254589e+08

Sheet Saldos X Terceros X Año
A4: Suma de Saldo | B4: AÑO
A5: TERCERO | B5: 2021 | C5: 2022 | D5: 2023 | E5: 2024 | F5: 2025 | G5: 2026 | H5: Total general
A6: ABDIEL ANTONIO SANJUR CORREA | C6: 82769 | D6: 464002 | E6: 23334 | H6: 570105
A7: ABRAM GARRIDO BARACALDO | F7: 2467400 | H7: 2467400
A8: ACOSTA MUÑOZ RAFAEL ENRIQUE | F8: 189800 | H8: 189800
A9: ACOSTA BALDOVINO LUIS CARLOS | E9: 1514488 | H9: 1514488
A10: ACOSTA FONTALVO JAIR ALFONSO | C10: 503875 | D10: 541334 | E10: -38667 | H10: 1006542
A11: ACOSTA FONTALVO WLADIMIR | D11: 43817 | E11: 43334 | H11: 87151
A12: ADALBERTO MANUEL OTERO MARTINEZ | C12: 1000001 | D12: 812001 | E12: 260000 | H12: 2072002
A13: AGAMEZ BELTRAN JAVIER ALFONZO | F13: 521950 | H13: 521950
A14: ALBEIRO SEGURA BOLAÑOS | C14: 162171 | H14: 162171
A15: ALCALA BARBOZA YENIS PATRICIA | C15: 666668 | D15: 889334 | E15: 86667 | F15: -47450 | H15: 1595219
A16: ALEJANDRO LUIS MARIN ROMERO | C16: 103721 | D16: 341332 | F16: 54371 | H16: 499424
A17: ALEJANDRO LUIS PEREZ PEDROZA | C17: 37832 | F17: 48077 | H17: 85909
A18: ALEXANDER LARA OROZCO | D18: 1317230 | E18: 767046 | H18: 2084276
A19: ALFONSO PATIÑO PUPO | C19: 103272 | D19: 43311 | H19: 146583
A20: ALFONSO JULIO CORREA | D20: 309335 | H20: 309335
A21: ALFONSO PESTANA GUETTE | E21: 433334 | H21: 433334
A22: ALVAREZ CASTRO KEIVIS MANUEL | C22: 33334 | H22: 33334
A23: ALVAREZ PIMIENTA WILL ALFONSO | E23: 698257 | F23: 759200 | H23: 1457457
A24: ALVAREZ QUIROZ DIEGO ARMANDO | E24: 46681 | H24: 46681
A25: ALVARO RAUL GOMEZ SANCHEZ | C25: 33334 | H25: 33334
A26: ANDRES SOLANA CASTILLA | F26: 790138 | H26: 790138
A27: ANDRES ENRIQUE ACEVEDO VILLADIEGO | C27: 33334 | H27: 33334
A28: ANDRES FELIPE TORRES PITALUA | E28: 346667 | F28: -129999 | H28: 216668
A29: ANDRES LAMBIS SALCEDO | F29: -47450 | H29: -47450
A30: ANGEL ENRIQUE PEREA SOLIPA | C30: 266667 | D30: 1 | F30: -266668 | H30: 0
A31: ANGULO PICOT JHONATAN | C31: 115442 | D31: 47691 | E31: 419904 | H31: 583037
A32: ANIBANIEL ARTEAGA ALTAMIRANDA | C32: 493876 | D32: 127151 | E32: 49997 | H32: 671024
A33: ANTONIO ANDRES ARRIETA ARROYO | C33: 37172 | H33: 37172
A34: ANTONIO BLANCO SIERRA | C34: 139328 | D34: 47209 | H34: 186537
A35: ANTONIO MANUEL DEL TORO GORDON | C35: 39976 | D35: 58969 | E35: 138057 | H35: 237002
A36: ARELLANO CAUSIL YEISSON | E36: 407720 | H36: 407720
A37: ARELLANO NEGRETE HERLING DAVID | D37: 184792 | E37: -134937 | H37: 49855
A38: ARGEMIRO AGRESOTH PADILLA | C38: 66668 | H38: 66668
A39: ARGEMIRO GUZMAN SANCHEZ | C39: 222227 | H39: 222227
A40: ARGUMEDO PACHECO RAMIRO ANTONIO | D40: 125809 | E40: 6702 | F40: -49031 | G40: 175246 | H40: 258726
A41: ARIAS ARRIETA JOSE ALFREDO | D41: 38667 | E41: 86668 | H41: 125335
A42: ARMANDO CASTELLANO ESPINOSA | E42: 475752 | H42: 475752
A43: ARNULFO HERNANDEZ MERCADO | C43: 357925 | D43: 850668 | E43: 2734311 | F43: 65049 | G43: 58364 | H43: 4066317
...

Sheet BD sin reclasif
A1: SUBSISTEMA DE CONTABILIDAD
A2: TRANSAMBIENTAL S.A.S.
A3: CONSULTA DE MOVIMIENTO POR FUENTES A 24.MAR./2026 | I3: Saldo a 2025
A4: PERIODO COMPRENDIDO ENTRE 01.ENE./2021 Y 28.FEB./2026 | I4: 1.7970636e+08 | J4: =SUBTOTAL(9,J7:J10000) -> 13425056 | K4: =SUBTOTAL(9,K7:K10000) -> 0 | L4: =+J4-K4 -> 13425056
A6: Codigo Cuenta | B6: Nombre Cuenta | C6: Fecha Documento | D6: Año | E6: Fuente | F6: Nombre Fuente | G6: Prefijo Documento | H6: Numero Documento | I6: Detalle del Registro | J6: Generado | K6: Reintegrado | L6: Saldo | M6: Tipo Anexo | N6: Id.Tercero | O6: Nombre Tercero | P6: Codigo Costo | Q6: Nombre Costo | R6: Codigo Retencion | S6: Concepto Retencion | T6: Base Retencion | U6: Tipo Libro | V6: Asiento Cierre | W6: Documento Referencia | X6: Numero Cheque | Y6: Codigo Operacion | Z6: Fecha Operacion | AA6: Programa | AB6: Estacion | AC6: Empresa | AD6: Fecha Version | AE6: Estado Reg. | AF6: Año 2 | AG6: Mes | AH6: eps
A7: 138020001 | B7: REINTEGRO DE INCAPACIDADES | C7: 44530 | D7: =TEXT(C7,"yyyy") -> 2021 | E7: 99 | F7: SALDOS INICIALES | H7: 000000001 | I7: REINTEGRO DE INCAPACIDADES | J7: 38623261 | K7: 0 | L7: =+J7-K7 -> 38623261 | M7: 1 | N7: 900771273 | O7: TRANSAMBIENTAL | T7: 0 | U7: CONTABLE | V7: N | W7: 000000001 | X7: 0 | Y7: TACOSITI | Z7: Feb 8 2022 4:17AM | AA7: frmCON6093 | AB7: DESKTOP-5900GRN | AC7: TAMBIENTAL | AD7: Feb 8 2022 4:17AM | AF7: =YEAR(C7) -> 2021 | AG7: =TEXT(C7,"mmm") -> nov | AH7: TRANSAMBIENTAL | AI7: #N/A
A8: 138020001 | B8: REINTEGRO DE INCAPACIDADES | C8: 44532 | D8: =TEXT(C8,"yyyy") -> 2021 | E8: 15 | F8: CONSIGNACIONES BANCO | H8: 000000010 | I8: EPS SURA COMPAÑIA SURAMERICANA SERVICIOS DE SALUD:REINTEGRO INCAPACIDAD SURAMERICANA000000010 | J8: 0 | K8: 262479 | L8: =+J8-K8 -> -262479 | M8: 1 | N8: 800088702 | O8: EPS SURA COMPAÑIA SURAMERICANA SERVICIOS DE SALUD | T8: 0 | U8: CONTABLE | V8: N | W8: 000000010 | X8: 0 | Y8: TACOTESO | Z8: Ene 14 2022 5:20PM | AA8: frmBAN607 | AB8: DESKTOP-O60S49G | AC8: TAMBIENTAL | AD8: Ene 14 2022 5:20PM | AF8: =YEAR(C8) -> 2021 | AG8: =TEXT(C8,"mmm") -> dic | AH8: EPS SURA COMPAÑIA SURAMERICANA SERVICIOS DE SALUD | AI8: #N/A
A9: 138020001 | B9: REINTEGRO DE INCAPACIDADES | C9: 44532 | D9: =TEXT(C9,"yyyy") -> 2021 | E9: 15 | F9: CONSIGNACIONES BANCO | H9: 000000011 | I9: SALUD TOTAL S.A. EPS ARS:REINTEGRO INCAPACIDAD SALUD TOTAL000000011 | J9: 0 | K9: 428175 | L9: =+J9-K9 -> -428175 | M9: 1 | N9: 800130907 | O9: SALUD TOTAL S.A. EPS ARS | T9: 0 | U9: CONTABLE | V9: N | W9: 000000011 | X9: 0 | Y9: TACOTESO | Z9: Ene 14 2022 5:27PM | AA9: frmBAN607 | AB9: DESKTOP-O60S49G | AC9: TAMBIENTAL | AD9: Ene 14 2022 5:27PM | AF9: =YEAR(C9) -> 2021 | AG9: =TEXT(C9,"mmm") -> dic | AH9: SALUD TOTAL S.A. EPS ARS | AI9: #N/A
A10: 138020001 | B10: REINTEGRO DE INCAPACIDADES | C10: 44540 | D10: =TEXT(C10,"yyyy") -> 2021 | E10: 15 | F10: CONSIGNACIONES BANCO | H10: 000000007 | I10: SALUD TOTAL S.A. EPS ARS:REINTEGRO INCAPACIDAD SALUD TOTAL000000007 | J10: 0 | K10: 1535787 | L10: =+J10-K10 -> -1535787 | M10: 1 | N10: 800130907 | O10: SALUD TOTAL S.A. EPS ARS | T10: 0 | U10: CONTABLE | V10: N | W10: 000000007 | X10: 0 | Y10: TACOTESO | Z10: Ene 14 2022 4:39PM | AA10: frmBAN607 | AB10: DESKTOP-O60S49G | AC10: TAMBIENTAL | AD10: Ene 14 2022 4:39PM | AF10: =YEAR(C10) -> 2021 | AG10: =TEXT(C10,"mmm") -> dic | AH10: SALUD TOTAL S.A. EPS ARS | AI10: #N/A
A11: 138020001 | B11: REINTEGRO DE INCAPACIDADES | C11: 44540 | D11: =TEXT(C11,"yyyy") -> 2021 | E11: 15 | F11: CONSIGNACIONES BANCO | H11: 000000008 | I11: NUEVA EMPRESA PROMOTORA DE SALUD:REINTEGRO INCAPACIDAD NUEVA EPS000000008 | J11: 0 | K11: 195079 | L11: =+J11-K11 -> -195079 | M11: 1 | N11: 900156264 | O11: NUEVA EMPRESA PROMOTORA DE SALUD | T11: 0 | U11: CONTABLE | V11: N | W11: 000000008 | X11: 0 | Y11: TACOTESO | Z11: Ene 14 2022 4:41PM | AA11: frmBAN607 | AB11: DESKTOP-O60S49G | AC11: TAMBIENTAL | AD11: Ene 14 2022 4:41PM | AF11: =YEAR(C11) -> 2021 | AG11: =TEXT(C11,"mmm") -> dic | AH11: NUEVA EMPRESA PROMOTORA DE SALUD | AI11: #N/A
A12: 138020001 | B12: REINTEGRO DE INCAPACIDADES | C12: 44545 | D12: =TEXT(C12,"yyyy") -> 2021 | E12: 21 | F12: NOMINA NOVASOFT | H12: 000000001 | I12: GASTOS REEMBOLSABLES | J12: 42866 | K12: 0 | L12: =+J12-K12 -> 42866 | M12: 1 | N12: 800088702 | O12: EPS SURA COMPAÑIA SURAMERICANA SERVICIOS DE SALUD | P12: 10010200 | Q12: COMPRAS Y ABASTESIMIENTO | T12: 0 | U12: CONTABLE | V12: N | W12: 000000001 | X12: 0 | Y12: TACOSITI | Z12: Feb 8 2022 5:24PM | AA12: frmCON6093 | AB12: DESKTOP-5900GRN | AC12: TAMBIENTAL | AD12: Feb 8 2022 5:24PM | AF12: =YEAR(C12) -> 2021 | AG12: =TEXT(C12,"mmm") -> dic | AH12: EPS SURA COMPAÑIA SURAMERICANA SERVICIOS DE SALUD | AI12: #N/A
A13: 138020001 | B13: REINTEGRO DE INCAPACIDADES | C13: 44545 | D13: =TEXT(C13,"yyyy") -> 2021 | E13: 21 | F13: NOMINA NOVASOFT | H13: 000000001 | I13: GASTOS REEMBOLSABLES | J13: 30284 | K13: 0 | L13: =+J13-K13 -> 30284 | M13: 1 | N13: 800088702 | O13: EPS SURA COMPAÑIA SURAMERICANA SERVICIOS DE SALUD | P13: 10020200 | Q13: EJECUCIÓN | T13: 0 | U13: CONTABLE | V13: N | W13: 000000001 | X13: 0 | Y13: TACOSITI | Z13: Feb 8 2022 5:24PM | AA13: frmCON6093 | AB13: DESKTOP-5900GRN | AC13: TAMBIENTAL | AD13: Feb 8 2022 5:24PM | AF13: =YEAR(C13) -> 2021 | AG13: =TEXT(C13,"mmm") -> dic | AH13: EPS SURA COMPAÑIA SURAMERICANA SERVICIOS DE SALUD | AI13: #N/A
A14: 138020001 | B14: REINTEGRO DE INCAPACIDADES | C14: 44545 | D14: =TEXT(C14,"yyyy") -> 2021 | E14: 21 | F14: NOMINA NOVASOFT | H14: 000000001 | I14: GASTOS REEMBOLSABLES | J14: 77628 | K14: 0 | L14: =+J14-K14 -> 77628 | M14: 1 | N14: 800256161 | O14: ARP SURA | P14: 10020200 | Q14: EJECUCIÓN | T14: 0 | U14: CONTABLE | V14: N | W14: 000000001 | X14: 0 | Y14: TACOSITI | Z14: Feb 8 2022 5:24PM | AA14: frmCON6093 | AB14: DESKTOP-5900GRN | AC14: TAMBIENTAL | AD14: Feb 8 2022 5:24PM | AF14: =YEAR(C14) -> 2021 | AG14: =TEXT(C14,"mmm") -> dic | AH14: ARP SURA | AI14: #N/A
A15: 138020001 | B15: REINTEGRO DE INCAPACIDADES | C15: 44545 | D15: =TEXT(C15,"yyyy") -> 2021 | E15: 21 | F15: NOMINA NOVASOFT | H15: 000000001 | I15: GASTOS REEMBOLSABLES | J15: 60568 | K15: 0 | L15: =+J15-K15 -> 60568 | M15: 1 | N15: 800130907 | O15: SALUD TOTAL S.A. EPS ARS | P15: 10030200 | Q15: COORDINACIÓN DE OPERACIONES | T15: 0 | U15: CONTABLE | V15: N | W15: 000000001 | X15: 0 | Y15: TACOSITI | Z15: Feb 8 2022 5:24PM | AA15: frmCON6093 | AB15: DESKTOP-5900GRN | AC15: TAMBIENTAL | AD15: Feb 8 2022 5:24PM | AF15: =YEAR(C15) -> 2021 | AG15: =TEXT(C15,"mmm") -> dic | AH15: SALUD TOTAL S.A. EPS ARS | AI15: #N/A
A16: 138020001 | B16: REINTEGRO DE INCAPACIDADES | C16: 44545 | D16: =TEXT(C16,"yyyy") -> 2021 | E16: 21 | F16: NOMINA NOVASOFT | H16: 000000001 | I16: GASTOS REEMBOLSABLES | J16: 67244 | K16: 0 | L16: =+J16-K16 -> 67244 | M16: 1 | N16: 800088702 | O16: EPS SURA COMPAÑIA SURAMERICANA SERVICIOS DE SALUD | P16: 10030400 | Q16: OPERADORES | T16: 0 | U16: CONTABLE | V16: N | W16: 000000001 | X16: 0 | Y16: TACOSITI | Z16: Feb 8 2022 5:24PM | AA16: frmCON6093 | AB16: DESKTOP-5900GRN | AC16: TAMBIENTAL | AD16: Feb 8 2022 5:24PM | AF16: =YEAR(C16) -> 2021 | AG16: =TEXT(C16,"mmm") -> dic | AH16: EPS SURA COMPAÑIA SURAMERICANA SERVICIOS DE SALUD | AI16: #N/A
A17: 138020001 | B17: REINTEGRO DE INCAPACIDADES | C17: 44545 | D17: =TEXT(C17,"yyyy") -> 2021 | E17: 21 | F17: NOMINA NOVASOFT | H17: 000000001 | I17: GASTOS REEMBOLSABLES | J17: 454263 | K17: 0 | L17: =+J17-K17 -> 454263 | M17: 1 | N17: 800130907 | O17: SALUD TOTAL S.A. EPS ARS | P17: 10030400 | Q17: OPERADORES | T17: 0 | U17: CONTABLE | V17: N | W17: 000000001 | X17: 0 | Y17: TACOSITI | Z17: Feb 8 2022 5:24PM | AA17: frmCON6093 | AB17: DESKTOP-5900GRN | AC17: TAMBIENTAL | AD17: Feb 8 2022 5:24PM | AF17: =YEAR(C17) -> 2021 | AG17: =TEXT(C17,"mmm") -> dic | AH17: SALUD TOTAL S.A. EPS ARS | AI17: #N/A
A18: 138020001 | B18: REINTEGRO DE INCAPACIDADES | C18: 44545 | D18: =TEXT(C18,"yyyy") -> 2021 | E18: 21 | F18: NOMINA NOVASOFT | H18: 000000001 | I18: GASTOS REEMBOLSABLES | J18: 32965 | K18: 0 | L18: =+J18-K18 -> 32965 | M18: 1 | N18: 800130907 | O18: SALUD TOTAL S.A. EPS ARS | P18: 10030400 | Q18: OPERADORES | T18: 0 | U18: CONTABLE | V18: N | W18: 000000001 | X18: 0 | Y18: TACOSITI | Z18: Feb 8 2022 5:24PM | AA18: frmCON6093 | AB18: DESKTOP-5900GRN | AC18: TAMBIENTAL | AD18: Feb 8 2022 5:24PM | AF18: =YEAR(C18) -> 2021 | AG18: =TEXT(C18,"mmm") -> dic | AH18: SALUD TOTAL S.A. EPS ARS | AI18: #N/A
A19: 138020001 | B19: REINTEGRO DE INCAPACIDADES | C19: 44545 | D19: =TEXT(C19,"yyyy") -> 2021 | E19: 21 | F19: NOMINA NOVASOFT | H19: 000000001 | I19: GASTOS REEMBOLSABLES | J19: 163561 | K19: 0 | L19: =+J19-K19 -> 163561 | M19: 1 | N19: 800130907 | O19: SALUD TOTAL S.A. EPS ARS | P19: 10030400 | Q19: OPERADORES | T19: 0 | U19: CONTABLE | V19: N | W19: 000000001 | X19: 0 | Y19: TACOSITI | Z19: Feb 8 2022 5:24PM | AA19: frmCON6093 | AB19: DESKTOP-5900GRN | AC19: TAMBIENTAL | AD19: Feb 8 2022 5:24PM | AF19: =YEAR(C19) -> 2021 | AG19: =TEXT(C19,"mmm") -> dic | AH19: SALUD TOTAL S.A. EPS ARS | AI19: #N/A
A20: 138020001 | B20: REINTEGRO DE INCAPACIDADES | C20: 44545 | D20: =TEXT(C20,"yyyy") -> 2021 | E20: 21 | F20: NOMINA NOVASOFT | H20: 000000001 | I20: GASTOS REEMBOLSABLES | J20: 363410 | K20: 0 | L20: =+J20-K20 -> 363410 | M20: 1 | N20: 800251440 | O20: E.P.S. SANITAS S.A. | P20: 10030400 | Q20: OPERADORES | T20: 0 | U20: CONTABLE | V20: N | W20: 000000001 | X20: 0 | Y20: TACOSITI | Z20: Feb 8 2022 5:24PM | AA20: frmCON6093 | AB20: DESKTOP-5900GRN | AC20: TAMBIENTAL | AD20: Feb 8 2022 5:24PM | AF20: =YEAR(C20) -> 2021 | AG20: =TEXT(C20,"mmm") -> dic | AH20: E.P.S. SANITAS S.A. | AI20: #N/A
A21: 138020001 | B21: REINTEGRO DE INCAPACIDADES | C21: 44545 | D21: =TEXT(C21,"yyyy") -> 2021 | E21: 21 | F21: NOMINA NOVASOFT | H21: 000000001 | I21: GASTOS REEMBOLSABLES | J21: 60568 | K21: 0 | L21: =+J21-K21 -> 60568 | M21: 1 | N21: 800251440 | O21: E.P.S. SANITAS S.A. | P21: 10030400 | Q21: OPERADORES | T21: 0 | U21: CONTABLE | V21: N | W21: 000000001 | X21: 0 | Y21: TACOSITI | Z21: Feb 8 2022 5:24PM | AA21: frmCON6093 | AB21: DESKTOP-5900GRN | AC21: TAMBIENTAL | AD21: Feb 8 2022 5:24PM | AF21: =YEAR(C21) -> 2021 | AG21: =TEXT(C21,"mmm") -> dic | AH21: E.P.S. SANITAS S.A. | AI21: #N/A
A22: 138020001 | B22: REINTEGRO DE INCAPACIDADES | C22: 44545 | D22: =TEXT(C22,"yyyy") -> 2021 | E22: 21 | F22: NOMINA NOVASOFT | H22: 000000001 | I22: GASTOS REEMBOLSABLES | J22: 30284 | K22: 0 | L22: =+J22-K22 -> 30284 | M22: 1 | N22: 800251440 | O22: E.P.S. SANITAS S.A. | P22: 10030400 | Q22: OPERADORES | T22: 0 | U22: CONTABLE | V22: N | W22: 000000001 | X22: 0 | Y22: TACOSITI | Z22: Feb 8 2022 5:24PM | AA22: frmCON6093 | AB22: DESKTOP-5900GRN | AC22: TAMBIENTAL | AD22: Feb 8 2022 5:24PM | AF22: =YEAR(C22) -> 2021 | AG22: =TEXT(C22,"mmm") -> dic | AH22: E.P.S. SANITAS S.A. | AI22: #N/A
A23: 138020001 | B23: REINTEGRO DE INCAPACIDADES | C23: 44545 | D23: =TEXT(C23,"yyyy") -> 2021 | E23: 21 | F23: NOMINA NOVASOFT | H23: 000000001 | I23: GASTOS REEMBOLSABLES | J23: 31088 | K23: 0 | L23: =+J23-K23 -> 31088 | M23: 1 | N23: 806008394 | O23: ASOCIACION MUTUAL SER EMPRESA SOLIDARIA | P23: 10030400 | Q23: OPERADORES | T23: 0 | U23: CONTABLE | V23: N | W23: 000000001 | X23: 0 | Y23: TACOSITI | Z23: Feb 8 2022 5:24PM | AA23: frmCON6093 | AB23: DESKTOP-5900GRN | AC23: TAMBIENTAL | AD23: Feb 8 2022 5:24PM | AF23: =YEAR(C23) -> 2021 | AG23: =TEXT(C23,"mmm") -> dic | AH23: ASOCIACION MUTUAL SER EMPRESA SOLIDARIA | AI23: #N/A
... A25: 138020001 | B25: REINTEGRO DE INCAPACIDADES | C25: 44545 | D25: =TEXT(C25,"yyyy") -> 2021 | E25: 21 | F25: NOMINA NOVASOFT | H25: 000000001 | I25: GASTOS REEMBOLSABLES | J25: 513641 | K25: 0 | L25: =+J25-K25 -> 513641 | M25: 1 | N25: 900156264 | O25: NUEVA EMPRESA PROMOTORA DE SALUD | P25: 10030400 | Q25: OPERADORES | T25: 0 | U25: CONTABLE | V25: N | W25: 000000001 | X25: 0 | Y25: TACOSITI | Z25: Feb 8 2022 5:24PM | AA25: frmCON6093 | AB25: DESKTOP-5900GRN | AC25: TAMBIENTAL | AD25: Feb 8 2022 5:24PM | AF25: =YEAR(C25) -> 2021 | AG25: =TEXT(C25,"mmm") -> dic | AH25: NUEVA EMPRESA PROMOTORA DE SALUD | AI25: #N/A
A26: 138020001 | B26: REINTEGRO DE INCAPACIDADES | C26: 44553 | D26: =TEXT(C26,"yyyy") -> 2021 | E26: 15 | F26: CONSIGNACIONES BANCO | H26: 000000003 | I26: SALUD TOTAL S.A. EPS ARS:REINTEGRO INCAPACIDAD SALUD TOTAL000000003 | J26: 0 | K26: 885682 | L26: =+J26-K26 -> -885682 | M26: 1 | N26: 800130907 | O26: SALUD TOTAL S.A. EPS ARS | T26: 0 | U26: CONTABLE | V26: N | W26: 000000003 | X26: 0 | Y26: TACOTESO | Z26: Ene 14 2022 3:48PM | AA26: frmBAN607 | AB26: DESKTOP-O60S49G | AC26: TAMBIENTAL | AD26: Ene 14 2022 3:48PM | AF26: =YEAR(C26) -> 2021 | AG26: =TEXT(C26,"mmm") -> dic | AH26: SALUD TOTAL S.A. EPS ARS | AI26: #N/A
A27: 138020001 | B27: REINTEGRO DE INCAPACIDADES | C27: 44553 | D27: =TEXT(C27,"yyyy") -> 2021 | E27: 15 | F27: CONSIGNACIONES BANCO | H27: 000000004 | I27: SALUD TOTAL S.A. EPS ARS:REINTEGRO INCAPACIDAD SALUD TOTAL000000004 | J27: 0 | K27: 274266 | L27: =+J27-K27 -> -274266 | M27: 1 | N27: 800130907 | O27: SALUD TOTAL S.A. EPS ARS | T27: 0 | U27: CONTABLE | V27: N | W27: 000000004 | X27: 0 | Y27: TACOTESO | Z27: Ene 14 2022 3:51PM | AA27: frmBAN607 | AB27: DESKTOP-O60S49G | AC27: TAMBIENTAL | AD27: Ene 14 2022 3:51PM | AF27: =YEAR(C27) -> 2021 | AG27: =TEXT(C27,"mmm") -> dic | AH27: SALUD TOTAL S.A. EPS ARS | AI27: #N/A
A28: 138020001 | B28: REINTEGRO DE INCAPACIDADES | C28: 44553 | D28: =TEXT(C28,"yyyy") -> 2021 | E28: 15 | F28: CONSIGNACIONES BANCO | H28: 000000005 | I28: E.P.S. FAMISANAR LTDA. CAFAM COLSUBSIDIO:REINTEGRO INCAPACIDAD FAMISANAR000000005 | J28: 0 | K28: 97173 | L28: =+J28-K28 -> -97173 | M28: 1 | N28: 830003564 | O28: E.P.S. FAMISANAR LTDA. CAFAM COLSUBSIDIO | T28: 0 | U28: CONTABLE | V28: N | W28: 000000005 | X28: 0 | Y28: TACOTESO | Z28: Ene 14 2022 3:58PM | AA28: frmBAN607 | AB28: DESKTOP-O60S49G | AC28: TAMBIENTAL | AD28: Ene 14 2022 3:58PM | AF28: =YEAR(C28) -> 2021 | AG28: =TEXT(C28,"mmm") -> dic | AH28: E.P.S. FAMISANAR LTDA. CAFAM COLSUBSIDIO | AI28: #N/A
A29: 138020001 | B29: REINTEGRO DE INCAPACIDADES | C29: 44553 | D29: =TEXT(C29,"yyyy") -> 2021 | E29: 15 | F29: CONSIGNACIONES BANCO | H29: 000000006 | I29: EPS SURA COMPAÑIA SURAMERICANA SERVICIOS DE SALUD:REINTEGRO INCAPACIDAD SURAMERICANA000000006 | J29: 0 | K29: 97524 | L29: =+J29-K29 -> -97524 | M29: 1 | N29: 800088702 | O29: EPS SURA COMPAÑIA SURAMERICANA SERVICIOS DE SALUD | T29: 0 | U29: CONTABLE | V29: N | W29: 000000006 | X29: 0 | Y29: TACOTESO | Z29: Ene 14 2022 4:37PM | AA29: frmBAN607 | AB29: DESKTOP-O60S49G | AC29: TAMBIENTAL | AD29: Ene 14 2022 4:37PM | AF29: =YEAR(C29) -> 2021 | AG29: =TEXT(C29,"mmm") -> dic | AH29: EPS SURA COMPAÑIA SURAMERICANA SERVICIOS DE SALUD | AI29: #N/A
A30: 138020001 | B30: REINTEGRO DE INCAPACIDADES | C30: 44554 | D30: =TEXT(C30,"yyyy") -> 2021 | E30: 15 | F30: CONSIGNACIONES BANCO | H30: 000000015 | I30: ASOCIACION MUTUAL SER EMPRESA SOLIDARIA:Reintegro incapacidad Mutual SER000000015 | J30: 0 | K30: 31572 | L30: =+J30-K30 -> -31572 | M30: 1 | N30: 806008394 | O30: ASOCIACION MUTUAL SER EMPRESA SOLIDARIA | T30: 0 | U30: CONTABLE | V30: N | W30: 000000015 | X30: 0 | Y30: TACOTESO | Z30: Feb 15 2022 2:10PM | AA30: frmBAN607 | AB30: DESKTOP-O60S49G | AC30: TAMBIENTAL | AD30: Feb 15 2022 2:10PM | AF30: =YEAR(C30) -> 2021 | AG30: =TEXT(C30,"mmm") -> dic | AH30: ASOCIACION MUTUAL SER EMPRESA SOLIDARIA | AI30: #N/A
A31: 138020001 | B31: REINTEGRO DE INCAPACIDADES | C31: 44559 | D31: =TEXT(C31,"yyyy") -> 2021 | E31: 15 | F31: CONSIGNACIONES BANCO | H31: 000000001 | I31: SALUD TOTAL S.A. EPS ARS:Reintegro incapacidad Salud Total000000001 | J31: 0 | K31: 133255 | L31: =+J31-K31 -> -133255 | M31: 1 | N31: 800130907 | O31: SALUD TOTAL S.A. EPS ARS | T31: 0 | U31: CONTABLE | V31: N | W31: 000000001 | X31: 0 | Y31: TACOTESO | Z31: Ene 14 2022 2:07PM | AA31: frmBAN607 | AB31: DESKTOP-O60S49G | AC31: TAMBIENTAL | AD31: Ene 14 2022 2:07PM | AF31: =YEAR(C31) -> 2021 | AG31: =TEXT(C31,"mmm") -> dic | AH31: SALUD TOTAL S.A. EPS ARS | AI31: #N/A
A32: 138020001 | B32: REINTEGRO DE INCAPACIDADES | C32: 44561 | D32: =TEXT(C32,"yyyy") -> 2021 | E32: 21 | F32: NOMINA NOVASOFT | H32: 000000001 | I32: GASTOS REEMBOLSABLES | J32: 278990 | K32: 0 | L32: =+J32-K32 -> 278990 | M32: 1 | N32: 800256161 | O32: ARP SURA | P32: 10020200 | Q32: EJECUCIÓN | T32: 0 | U32: CONTABLE | V32: N | W32: 000000001 | X32: 0 | Y32: TACOSITI | Z32: Feb 8 2022 5:24PM | AA32: frmCON6093 | AB32: DESKTOP-5900GRN | AC32: TAMBIENTAL | AD32: Feb 8 2022 5:24PM | AF32: =YEAR(C32) -> 2021 | AG32: =TEXT(C32,"mmm") -> dic | AH32: ARP SURA | AI32: #N/A
A33: 138020001 | B33: REINTEGRO DE INCAPACIDADES | C33: 44561 | D33: =TEXT(C33,"yyyy") -> 2021 | E33: 21 | F33: NOMINA NOVASOFT | H33: 000000001 | I33: GASTOS REEMBOLSABLES | J33: 33082 | K33: 0 | L33: =+J33-K33 -> 33082 | M33: 1 | N33: 800088702 | O33: EPS SURA COMPAÑIA SURAMERICANA SERVICIOS DE SALUD | P33: 10030400 | Q33: OPERADORES | T33: 0 | U33: CONTABLE | V33: N | W33: 000000001 | X33: 0 | Y33: TACOSITI | Z33: Feb 8 2022 5:24PM | AA33: frmCON6093 | AB33: DESKTOP-5900GRN | AC33: TAMBIENTAL | AD33: Feb 8 2022 5:24PM | AF33: =YEAR(C33) -> 2021 | AG33: =TEXT(C33,"mmm") -> dic | AH33: EPS SURA COMPAÑIA SURAMERICANA SERVICIOS DE SALUD | AI33: #N/A
A34: 138020001 | B34: REINTEGRO DE INCAPACIDADES | C34: 44561 | D34: =TEXT(C34,"yyyy") -> 2021 | E34: 21 | F34: NOMINA NOVASOFT | H34: 000000001 | I34: GASTOS REEMBOLSABLES | J34: 68499 | K34: 0 | L34: =+J34-K34 -> 68499 | M34: 1 | N34: 800088702 | O34: EPS SURA COMPAÑIA SURAMERICANA SERVICIOS DE SALUD | P34: 10030400 | Q34: OPERADORES | T34: 0 | U34: CONTABLE | V34: N | W34: 000000001 | X34: 0 | Y34: TACOSITI | Z34: Feb 8 2022 5:24PM | AA34: frmCON6093 | AB34: DESKTOP-5900GRN | AC34: TAMBIENTAL | AD34: Feb 8 2022 5:24PM | AF34: =YEAR(C34) -> 2021 | AG34: =TEXT(C34,"mmm") -> dic | AH34: EPS SURA COMPAÑIA SURAMERICANA SERVICIOS DE SALUD | AI34: #N/A
A35: 138020001 | B35: REINTEGRO DE INCAPACIDADES | C35: 44561 | D35: =TEXT(C35,"yyyy") -> 2021 | E35: 21 | F35: NOMINA NOVASOFT | H35: 000000001 | I35: GASTOS REEMBOLSABLES | J35: 484547 | K35: 0 | L35: =+J35-K35 -> 484547 | M35: 1 | N35: 800130907 | O35: SALUD TOTAL S.A. EPS ARS | P35: 10030400 | Q35: OPERADORES | T35: 0 | U35: CONTABLE | V35: N | W35: 000000001 | X35: 0 | Y35: TACOSITI | Z35: Feb 8 2022 5:24PM | AA35: frmCON6093 | AB35: DESKTOP-5900GRN | AC35: TAMBIENTAL | AD35: Feb 8 2022 5:24PM | AF35: =YEAR(C35) -> 2021 | AG35: =TEXT(C35,"mmm") -> dic | AH35: SALUD TOTAL S.A. EPS ARS | AI35: #N/A
A36: 138020001 | B36: REINTEGRO DE INCAPACIDADES | C36: 44561 | D36: =TEXT(C36,"yyyy") -> 2021 | E36: 21 | F36: NOMINA NOVASOFT | H36: 000000001 | I36: GASTOS REEMBOLSABLES | J36: 30881 | K36: 0 | L36: =+J36-K36 -> 30881 | M36: 1 | N36: 800130907 | O36: SALUD TOTAL S.A. EPS ARS | P36: 10030400 | Q36: OPERADORES | T36: 0 | U36: CONTABLE | V36: N | W36: 000000001 | X36: 0 | Y36: TACOSITI | Z36: Feb 8 2022 5:24PM | AA36: frmCON6093 | AB36: DESKTOP-5900GRN | AC36: TAMBIENTAL | AD36: Feb 8 2022 5:24PM | AF36: =YEAR(C36) -> 2021 | AG36: =TEXT(C36,"mmm") -> dic | AH36: SALUD TOTAL S.A. EPS ARS | AI36: #N/A
A37: 138020001 | B37: REINTEGRO DE INCAPACIDADES | C37: 44561 | D37: =TEXT(C37,"yyyy") -> 2021 | E37: 21 | F37: NOMINA NOVASOFT | H37: 000000001 | I37: GASTOS REEMBOLSABLES | J37: 102302 | K37: 0 | L37: =+J37-K37 -> 102302 | M37: 1 | N37: 800130907 | O37: SALUD TOTAL S.A. EPS ARS | P37: 10030400 | Q37: OPERADORES | T37: 0 | U37: CONTABLE | V37: N | W37: 000000001 | X37: 0 | Y37: TACOSITI | Z37: Feb 8 2022 5:24PM | AA37: frmCON6093 | AB37: DESKTOP-5900GRN | AC37: TAMBIENTAL | AD37: Feb 8 2022 5:24PM | AF37: =YEAR(C37) -> 2021 | AG37: =TEXT(C37,"mmm") -> dic | AH37: SALUD TOTAL S.A. EPS ARS | AI37: #N/A
A38: 138020001 | B38: REINTEGRO DE INCAPACIDADES | C38: 44561 | D38: =TEXT(C38,"yyyy") -> 2021 | E38: 21 | F38: NOMINA NOVASOFT | H38: 000000001 | I38: GASTOS REEMBOLSABLES | J38: 98137 | K38: 0 | L38: =+J38-K38 -> 98137 | M38: 1 | N38: 800130907 | O38: SALUD TOTAL S.A. EPS ARS | P38: 10030400 | Q38: OPERADORES | T38: 0 | U38: CONTABLE | V38: N | W38: 000000001 | X38: 0 | Y38: TACOSITI | Z38: Feb 8 2022 5:24PM | AA38: frmCON6093 | AB38: DESKTOP-5900GRN | AC38: TAMBIENTAL | AD38: Feb 8 2022 5:24PM | AF38: =YEAR(C38) -> 2021 | AG38: =TEXT(C38,"mmm") -> dic | AH38: SALUD TOTAL S.A. EPS ARS | AI38: #N/A
A39: 138020001 | B39: REINTEGRO DE INCAPACIDADES | C39: 44561 | D39: =TEXT(C39,"yyyy") -> 2021 | E39: 21 | F39: NOMINA NOVASOFT | H39: 000000001 | I39: GASTOS REEMBOLSABLES | J39: 34357 | K39: 0 | L39: =+J39-K39 -> 34357 | M39: 1 | N39: 800130907 | O39: SALUD TOTAL S.A. EPS ARS | P39: 10030400 | Q39: OPERADORES | T39: 0 | U39: CONTABLE | V39: N | W39: 000000001 | X39: 0 | Y39: TACOSITI | Z39: Feb 8 2022 5:24PM | AA39: frmCON6093 | AB39: DESKTOP-5900GRN | AC39: TAMBIENTAL | AD39: Feb 8 2022 5:24PM | AF39: =YEAR(C39) -> 2021 | AG39: =TEXT(C39,"mmm") -> dic | AH39: SALUD TOTAL S.A. EPS ARS | AI39: #N/A
A40: 138020001 | B40: REINTEGRO DE INCAPACIDADES | C40: 44561 | D40: =TEXT(C40,"yyyy") -> 2021 | E40: 21 | F40: NOMINA NOVASOFT | H40: 000000001 | I40: GASTOS REEMBOLSABLES | J40: 363411 | K40: 0 | L40: =+J40-K40 -> 363411 | M40: 1 | N40: 800251440 | O40: E.P.S. SANITAS S.A. | P40: 10030400 | Q40: OPERADORES | T40: 0 | U40: CONTABLE | V40: N | W40: 000000001 | X40: 0 | Y40: TACOSITI | Z40: Feb 8 2022 5:24PM | AA40: frmCON6093 | AB40: DESKTOP-5900GRN | AC40: TAMBIENTAL | AD40: Feb 8 2022 5:24PM | AF40: =YEAR(C40) -> 2021 | AG40: =TEXT(C40,"mmm") -> dic | AH40: E.P.S. SANITAS S.A. | AI40: #N/A
A41: 138020001 | B41: REINTEGRO DE INCAPACIDADES | C41: 44561 | D41: =TEXT(C41,"yyyy") -> 2021 | E41: 21 | F41: NOMINA NOVASOFT | H41: 000000001 | I41: GASTOS REEMBOLSABLES | J41: 33912 | K41: 0 | L41: =+J41-K41 -> 33912 | M41: 1 | N41: 800251440 | O41: E.P.S. SANITAS S.A. | P41: 10030400 | Q41: OPERADORES | T41: 0 | U41: CONTABLE | V41: N | W41: 000000001 | X41: 0 | Y41: TACOSITI | Z41: Feb 8 2022 5:24PM | AA41: frmCON6093 | AB41: DESKTOP-5900GRN | AC41: TAMBIENTAL | AD41: Feb 8 2022 5:24PM | AF41: =YEAR(C41) -> 2021 | AG41: =TEXT(C41,"mmm") -> dic | AH41: E.P.S. SANITAS S.A. | AI41: #N/A
A42: 138020001 | B42: REINTEGRO DE INCAPACIDADES | C42: 44561 | D42: =TEXT(C42,"yyyy") -> 2021 | E42: 21 | F42: NOMINA NOVASOFT | H42: 000000001 | I42: GASTOS REEMBOLSABLES | J42: 345056 | K42: 0 | L42: =+J42-K42 -> 345056 | M42: 1 | N42: 830003564 | O42: E.P.S. FAMISANAR LTDA. CAFAM COLSUBSIDIO | P42: 10030400 | Q42: OPERADORES | T42: 0 | U42: CONTABLE | V42: N | W42: 000000001 | X42: 0 | Y42: TACOSITI | Z42: Feb 8 2022 5:24PM | AA42: frmCON6093 | AB42: DESKTOP-5900GRN | AC42: TAMBIENTAL | AD42: Feb 8 2022 5:24PM | AF42: =YEAR(C42) -> 2021 | AG42: =TEXT(C42,"mmm") -> dic | AH42: E.P.S. FAMISANAR LTDA. CAFAM COLSUBSIDIO | AI42: #N/A
...

Sheet BD 2021 - 2026
A1: SUBSISTEMA DE CONTABILIDAD
A2: TRANSAMBIENTAL S.A.S.
A3: CONSULTA DE MOVIMIENTO POR FUENTES A 24.MAR./2026
A4: PERIODO COMPRENDIDO ENTRE 01.ENE./2021 Y 28.FEB./2026 | I4: =SUBTOTAL(9,I7:I10000) -> 13425056 | J4: =SUBTOTAL(9,J7:J10000) -> 10261364 | K4: =+I4-J4 -> 3163692
A6: Codigo Cuenta | B6: Nombre Cuenta | C6: Fecha Documento | D6: Fuente | E6: Nombre Fuente | F6: Prefijo Documento | G6: Numero Documento | H6: Detalle del Registro | I6: Valor Debito | J6: Valor Credito | K6: Tipo Anexo | L6: Id.Tercero | M6: Nombre Tercero | N6: Codigo Costo | O6: Nombre Costo | P6: Codigo Retencion | Q6: Concepto Retencion | R6: Base Retencion | S6: Tipo Libro | T6: Asiento Cierre | U6: Documento Referencia | V6: Numero Cheque | W6: Codigo Operacion | X6: Fecha Operacion | Y6: Programa | Z6: Estacion | AA6: Empresa | AB6: Fecha Version | AC6: Estado Reg.
A7: 138020001 | B7: REINTEGRO DE INCAPACIDADES | C7: 44530 | D7: 99 | E7: SALDOS INICIALES | G7: 000000001 | H7: REINTEGRO DE INCAPACIDADES | I7: 38623261 | J7: 0 | K7: 1 | L7: 900771273 | M7: TRANSAMBIENTAL | R7: 0 | S7: CONTABLE | T7: N | U7: 000000001 | V7: 0 | W7: TACOSITI | X7: Feb 8 2022 4:17AM | Y7: frmCON6093 | Z7: DESKTOP-5900GRN | AA7: TAMBIENTAL | AB7: Feb 8 2022 4:17AM
A8: 138020001 | B8: REINTEGRO DE INCAPACIDADES | C8: 44532 | D8: 15 | E8: CONSIGNACIONES BANCO | G8: 000000010 | H8: EPS SURA COMPAÑIA SURAMERICANA SERVICIOS DE SALUD:REINTEGRO INCAPACIDAD SURAMERICANA000000010 | I8: 0 | J8: 262479 | K8: 1 | L8: 800088702 | M8: EPS SURA COMPAÑIA SURAMERICANA SERVICIOS DE SALUD | R8: 0 | S8: CONTABLE | T8: N | U8: 000000010 | V8: 0 | W8: TACOTESO | X8: Ene 14 2022 5:20PM | Y8: frmBAN607 | Z8: DESKTOP-O60S49G | AA8: TAMBIENTAL | AB8: Ene 14 2022 5:20PM
A9: 138020001 | B9: REINTEGRO DE INCAPACIDADES | C9: 44532 | D9: 15 | E9: CONSIGNACIONES BANCO | G9: 000000011 | H9: SALUD TOTAL S.A. EPS ARS:REINTEGRO INCAPACIDAD SALUD TOTAL000000011 | I9: 0 | J9: 428175 | K9: 1 | L9: 800130907 | M9: SALUD TOTAL S.A. EPS ARS | R9: 0 | S9: CONTABLE | T9: N | U9: 000000011 | V9: 0 | W9: TACOTESO | X9: Ene 14 2022 5:27PM | Y9: frmBAN607 | Z9: DESKTOP-O60S49G | AA9: TAMBIENTAL | AB9: Ene 14 2022 5:27PM
A10: 138020001 | B10: REINTEGRO DE INCAPACIDADES | C10: 44540 | D10: 15 | E10: CONSIGNACIONES BANCO | G10: 000000007 | H10: SALUD TOTAL S.A. EPS ARS:REINTEGRO INCAPACIDAD SALUD TOTAL000000007 | I10: 0 | J10: 1535787 | K10: 1 | L10: 800130907 | M10: SALUD TOTAL S.A. EPS ARS | R10: 0 | S10: CONTABLE | T10: N | U10: 000000007 | V10: 0 | W10: TACOTESO | X10: Ene 14 2022 4:39PM | Y10: frmBAN607 | Z10: DESKTOP-O60S49G | AA10: TAMBIENTAL | AB10: Ene 14 2022 4:39PM
A11: 138020001 | B11: REINTEGRO DE INCAPACIDADES | C11: 44540 | D11: 15 | E11: CONSIGNACIONES BANCO | G11: 000000008 | H11: NUEVA EMPRESA PROMOTORA DE SALUD:REINTEGRO INCAPACIDAD NUEVA EPS000000008 | I11: 0 | J11: 195079 | K11: 1 | L11: 900156264 | M11: NUEVA EMPRESA PROMOTORA DE SALUD | R11: 0 | S11: CONTABLE | T11: N | U11: 000000008 | V11: 0 | W11: TACOTESO | X11: Ene 14 2022 4:41PM | Y11: frmBAN607 | Z11: DESKTOP-O60S49G | AA11: TAMBIENTAL | AB11: Ene 14 2022 4:41PM
A12: 138020001 | B12: REINTEGRO DE INCAPACIDADES | C12: 44545 | D12: 21 | E12: NOMINA NOVASOFT | G12: 000000001 | H12: GASTOS REEMBOLSABLES | I12: 42866 | J12: 0 | K12: 1 | L12: 800088702 | M12: EPS SURA COMPAÑIA SURAMERICANA SERVICIOS DE SALUD | N12: 10010200 | O12: COMPRAS Y ABASTESIMIENTO | R12: 0 | S12: CONTABLE | T12: N | U12: 000000001 | V12: 0 | W12: TACOSITI | X12: Feb 8 2022 5:24PM | Y12: frmCON6093 | Z12: DESKTOP-5900GRN | AA12: TAMBIENTAL | AB12: Feb 8 2022 5:24PM
A13: 138020001 | B13: REINTEGRO DE INCAPACIDADES | C13: 44545 | D13: 21 | E13: NOMINA NOVASOFT | G13: 000000001 | H13: GASTOS REEMBOLSABLES | I13: 30284 | J13: 0 | K13: 1 | L13: 800088702 | M13: EPS SURA COMPAÑIA SURAMERICANA SERVICIOS DE SALUD | N13: 10020200 | O13: EJECUCIÓN | R13: 0 | S13: CONTABLE | T13: N | U13: 000000001 | V13: 0 | W13: TACOSITI | X13: Feb 8 2022 5:24PM | Y13: frmCON6093 | Z13: DESKTOP-5900GRN | AA13: TAMBIENTAL | AB13: Feb 8 2022 5:24PM
A14: 138020001 | B14: REINTEGRO DE INCAPACIDADES | C14: 44545 | D14: 21 | E14: NOMINA NOVASOFT | G14: 000000001 | H14: GASTOS REEMBOLSABLES | I14: 77628 | J14: 0 | K14: 1 | L14: 800256161 | M14: ARP SURA | N14: 10020200 | O14: EJECUCIÓN | R14: 0 | S14: CONTABLE | T14: N | U14: 000000001 | V14: 0 | W14: TACOSITI | X14: Feb 8 2022 5:24PM | Y14: frmCON6093 | Z14: DESKTOP-5900GRN | AA14: TAMBIENTAL | AB14: Feb 8 2022 5:24PM
A15: 138020001 | B15: REINTEGRO DE INCAPACIDADES | C15: 44545 | D15: 21 | E15: NOMINA NOVASOFT | G15: 000000001 | H15: GASTOS REEMBOLSABLES | I15: 60568 | J15: 0 | K15: 1 | L15: 800130907 | M15: SALUD TOTAL S.A. EPS ARS | N15: 10030200 | O15: COORDINACIÓN DE OPERACIONES | R15: 0 | S15: CONTABLE | T15: N | U15: 000000001 | V15: 0 | W15: TACOSITI | X15: Feb 8 2022 5:24PM | Y15: frmCON6093 | Z15: DESKTOP-5900GRN | AA15: TAMBIENTAL | AB15: Feb 8 2022 5:24PM
A16: 138020001 | B16: REINTEGRO DE INCAPACIDADES | C16: 44545 | D16: 21 | E16: NOMINA NOVASOFT | G16: 000000001 | H16: GASTOS REEMBOLSABLES | I16: 67244 | J16: 0 | K16: 1 | L16: 800088702 | M16: EPS SURA COMPAÑIA SURAMERICANA SERVICIOS DE SALUD | N16: 10030400 | O16: OPERADORES | R16: 0 | S16: CONTABLE | T16: N | U16: 000000001 | V16: 0 | W16: TACOSITI | X16: Feb 8 2022 5:24PM | Y16: frmCON6093 | Z16: DESKTOP-5900GRN | AA16: TAMBIENTAL | AB16: Feb 8 2022 5:24PM
A17: 138020001 | B17: REINTEGRO DE INCAPACIDADES | C17: 44545 | D17: 21 | E17: NOMINA NOVASOFT | G17: 000000001 | H17: GASTOS REEMBOLSABLES | I17: 454263 | J17: 0 | K17: 1 | L17: 800130907 | M17: SALUD TOTAL S.A. EPS ARS | N17: 10030400 | O17: OPERADORES | R17: 0 | S17: CONTABLE | T17: N | U17: 000000001 | V17: 0 | W17: TACOSITI | X17: Feb 8 2022 5:24PM | Y17: frmCON6093 | Z17: DESKTOP-5900GRN | AA17: TAMBIENTAL | AB17: Feb 8 2022 5:24PM
A18: 138020001 | B18: REINTEGRO DE INCAPACIDADES | C18: 44545 | D18: 21 | E18: NOMINA NOVASOFT | G18: 000000001 | H18: GASTOS REEMBOLSABLES | I18: 32965 | J18: 0 | K18: 1 | L18: 800130907 | M18: SALUD TOTAL S.A. EPS ARS | N18: 10030400 | O18: OPERADORES | R18: 0 | S18: CONTABLE | T18: N | U18: 000000001 | V18: 0 | W18: TACOSITI | X18: Feb 8 2022 5:24PM | Y18: frmCON6093 | Z18: DESKTOP-5900GRN | AA18: TAMBIENTAL | AB18: Feb 8 2022 5:24PM
A19: 138020001 | B19: REINTEGRO DE INCAPACIDADES | C19: 44545 | D19: 21 | E19: NOMINA NOVASOFT | G19: 000000001 | H19: GASTOS REEMBOLSABLES | I19: 163561 | J19: 0 | K19: 1 | L19: 800130907 | M19: SALUD TOTAL S.A. EPS ARS | N19: 10030400 | O19: OPERADORES | R19: 0 | S19: CONTABLE | T19: N | U19: 000000001 | V19: 0 | W19: TACOSITI | X19: Feb 8 2022 5:24PM | Y19: frmCON6093 | Z19: DESKTOP-5900GRN | AA19: TAMBIENTAL | AB19: Feb 8 2022 5:24PM
A20: 138020001 | B20: REINTEGRO DE INCAPACIDADES | C20: 44545 | D20: 21 | E20: NOMINA NOVASOFT | G20: 000000001 | H20: GASTOS REEMBOLSABLES | I20: 363410 | J20: 0 | K20: 1 | L20: 800251440 | M20: E.P.S. SANITAS S.A. | N20: 10030400 | O20: OPERADORES | R20: 0 | S20: CONTABLE | T20: N | U20: 000000001 | V20: 0 | W20: TACOSITI | X20: Feb 8 2022 5:24PM | Y20: frmCON6093 | Z20: DESKTOP-5900GRN | AA20: TAMBIENTAL | AB20: Feb 8 2022 5:24PM
A21: 138020001 | B21: REINTEGRO DE INCAPACIDADES | C21: 44545 | D21: 21 | E21: NOMINA NOVASOFT | G21: 000000001 | H21: GASTOS REEMBOLSABLES | I21: 60568 | J21: 0 | K21: 1 | L21: 800251440 | M21: E.P.S. SANITAS S.A. | N21: 10030400 | O21: OPERADORES | R21: 0 | S21: CONTABLE | T21: N | U21: 000000001 | V21: 0 | W21: TACOSITI | X21: Feb 8 2022 5:24PM | Y21: frmCON6093 | Z21: DESKTOP-5900GRN | AA21: TAMBIENTAL | AB21: Feb 8 2022 5:24PM
